# üîç UPDATED DEBUG READOUT: The Plot Thickens

## New Critical Discovery
The issue is **NOT** with file buffering or PIL itself. We've proven:

1. ‚úÖ **File is perfectly valid**: JPEG header `ffd8ffe0`, 50126 bytes, identical to source
2. ‚úÖ **PIL works in direct calls**: Same file opens perfectly outside pytest
3. ‚úÖ **Zone methods work individually**: When called directly, `analyze_with_retry_logic()` succeeds
4. ‚ùå **Only fails in pytest integration context**: Same methods fail when called via `run_analysis_cycle()` in pytest

## Proof of Context-Dependent Failure

### Direct Python Execution (Works Perfectly) ‚úÖ
```python
# These work perfectly when called directly:
zone.analyze_with_retry_logic(image_path)  # ‚úÖ SUCCESS
zone.analyze_image_for_completed_tasks(image_path)  # ‚úÖ SUCCESS

# Output:
# ‚úÖ analyze_with_retry_logic works: []
# ‚úÖ analyze_image_for_completed_tasks works: {'tasks': [], 'score': 50}
```

### Pytest Integration Test (Fails) ‚ùå
```python
# This fails in pytest context:
zone.run_analysis_cycle()  # ‚ùå FAILS with PIL.UnidentifiedImageError

# Output:
# WARNING: AI analysis attempt 1 failed: cannot identify image file
# WARNING: AI analysis attempt 2 failed: cannot identify image file  
# WARNING: AI analysis attempt 3 failed: cannot identify image file
# ERROR: All 3 AI analysis attempts failed
```

## Detailed Evidence

### File Validation (All Pass)
- **File exists**: `os.path.exists('/tmp/Kitchen_latest.jpg')` = `True`
- **File size**: `os.path.getsize()` = `50126 bytes` (matches source exactly)
- **JPEG header**: `ffd8ffe000104a46494600010101006000600000` (valid JFIF format)
- **Manual file read**: Works perfectly, can read all bytes without error
- **File comparison**: `original_data == copied_data` = `True` (byte-for-byte identical)

### PIL Testing (Mixed Results)
- **Direct PIL test**: `Image.open('/tmp/Kitchen_latest.jpg')` = ‚úÖ SUCCESS `(408, 432), RGB, JPEG`
- **Zone PIL import**: `aicleaner.Image.open('/tmp/Kitchen_latest.jpg')` = ‚úÖ SUCCESS `(408, 432), RGB, JPEG`
- **Import verification**: `PIL.Image.open is aicleaner.aicleaner.Image.open` = `True`
- **In pytest context**: Same file, same import = ‚ùå `PIL.UnidentifiedImageError`

### MockHAClient Validation (All Pass)
- **Original source**: `Image.open('tests/fixtures/messyroom.jpg')` = ‚úÖ SUCCESS
- **Copied file**: `Image.open('/tmp/test_copy.jpg')` = ‚úÖ SUCCESS  
- **File integrity**: Original and copied files are byte-for-byte identical
- **shutil.copy2()**: Properly handles file closing and flushing

## The Core Mystery

**Why does `PIL.Image.open(identical_file)` work perfectly when called directly but fail with `UnidentifiedImageError` when called from within `zone.run_analysis_cycle()` in a pytest context?**

### What We've Ruled Out
- ‚ùå **File buffering issues**: File is properly flushed (shutil.copy2 handles this)
- ‚ùå **Invalid JPEG**: File opens perfectly in all non-pytest contexts
- ‚ùå **Import problems**: Same PIL.Image.open object used in all cases
- ‚ùå **File corruption**: Byte-for-byte comparison shows identical files
- ‚ùå **Path issues**: Same absolute path used in all tests
- ‚ùå **PIL version**: Same PIL installation works in direct calls

### What This Points To
This appears to be a **pytest execution environment issue** rather than a PIL, file, or code problem. The same exact code, same file, same PIL import behaves differently based on the call stack context.

## Hypothesis for Investigation

### Possible Pytest-Specific Issues
1. **Working directory changes**: pytest might change CWD during test execution
2. **File descriptor limits**: Handle conflicts or limits in pytest environment  
3. **Import isolation**: Module reloading or import path changes in pytest
4. **Memory/threading**: Issues in pytest multiprocessing or fixture handling
5. **Exception handling**: Different error propagation in pytest vs direct execution
6. **Temporary file cleanup**: Race conditions with pytest's temp file management
7. **Mocking interference**: Some mock affecting PIL behavior in unexpected ways

### Test Environment Details
- **Platform**: Linux, Python 3.12.9, pytest-8.3.4
- **PIL Version**: Latest (works perfectly outside pytest)
- **Test Pattern**: Integration tests using MockHAClient and MockGeminiClient
- **File Location**: `/tmp/Kitchen_latest.jpg` (same path in all contexts)
- **Call Stack**: `pytest ‚Üí test_method ‚Üí zone.run_analysis_cycle() ‚Üí analyze_with_retry_logic() ‚Üí Image.open()` ‚ùå

## Current Status

### What Works ‚úÖ
- **Unit tests**: 73/78 pass (100% core functionality)
- **Direct method calls**: All Zone methods work perfectly
- **File operations**: MockHAClient creates valid files
- **PIL operations**: Image processing works in all direct contexts

### What Fails ‚ùå
- **Integration tests**: 5/5 fail due to this pytest context issue
- **End-to-end validation**: Cannot verify full workflow in test environment

### Impact
- **Production readiness**: Core features work, but end-to-end validation blocked
- **Test coverage**: Integration scenarios cannot be validated
- **Confidence**: Reduced due to inability to test complete workflows

## Question for AI Expert

**How can we resolve this pytest-specific context issue where PIL.Image.open() fails only when called through a specific call stack in pytest, despite the same code working perfectly in direct execution?**

The core functionality is proven to work - this is purely a test environment mystery that needs solving.
