# üîç DEBUG READOUT: Integration Test Image.open Failure

## Problem Summary
AICleaner v2.0 integration tests are failing because `PIL.Image.open()` cannot identify image files, but ONLY when called from within Zone analysis methods. Direct PIL calls work perfectly.

## Test Environment
- **Platform**: Linux, Python 3.12.9, pytest-8.3.4
- **PIL Version**: Latest (installed via pip)
- **Image File**: Real room photo (messyroom.jpg, 50126 bytes, 408x432 RGB JPEG)
- **File Location**: `/tmp/Kitchen_latest.jpg` (copied from valid source)

## What Works ‚úÖ
1. **Direct PIL access**: `Image.open('/tmp/Kitchen_latest.jpg')` works perfectly
2. **MockHAClient**: Successfully copies valid JPEG (50126 bytes, exact match)
3. **File validation**: `os.path.exists()` returns True, file size correct
4. **Unit tests**: 73/78 tests pass, including all notification functionality

## What Fails ‚ùå
5 integration tests fail with identical error: `PIL.UnidentifiedImageError: cannot identify image file '/tmp/Kitchen_latest.jpg'`

## Debug Script Output
```
=== DEBUG INTEGRATION TEST ===
Zone created: Kitchen

--- Testing camera snapshot ---
Image path: /tmp/Kitchen_latest.jpg
File exists: True
File size: 50126 bytes
PIL can open: (408, 432)  ‚Üê WORKS PERFECTLY

--- Testing individual analysis methods ---
Testing analyze_with_retry_logic...
AI analysis attempt 1 failed: cannot identify image file  ‚Üê FAILS
Result: None
Gemini calls so far: 0

Testing analyze_with_confidence_scoring...
Error in confidence scoring: cannot identify image file  ‚Üê FAILS
Result: None
```

## Key Contradiction
- **Direct call**: `Image.open(image_path)` ‚Üí SUCCESS ‚úÖ
- **From Zone method**: `Image.open(image_path)` ‚Üí `UnidentifiedImageError` ‚ùå
- **Same file, same path, same process**

## Code Context
The failing call is in `analyze_with_retry_logic()`:
```python
for attempt in range(max_retries):
    try:
        img = Image.open(image_path)  # ‚Üê FAILS HERE
        # ... rest of method
```

## Attempted Solutions (All Failed)
1. ‚úÖ **Real photo**: Using actual room JPEG instead of synthetic images
2. ‚úÖ **File validation**: Verified file exists, correct size, valid format
3. ‚ùå **PIL patching**: Multiple patching strategies failed
4. ‚ùå **File handle fixes**: Tried various file closing/flushing approaches
5. ‚ùå **Path normalization**: Checked for path issues

## Hypothesis
There's a **context-dependent issue** where PIL behaves differently when called:
- Directly from script ‚úÖ
- From within Zone class methods ‚ùå

Possible causes:
1. **File locking**: File handle not properly released
2. **Working directory**: Different CWD affecting file access
3. **Import context**: PIL import behaving differently in different contexts
4. **Memory/threading**: Some interference in the Zone execution context
5. **Exception handling**: Error being caught and re-raised differently

## Question for AI
**Why would `PIL.Image.open(same_file)` work perfectly in direct calls but fail with `UnidentifiedImageError` when called from within a class method, using the exact same file path and the same Python process?**

The file is demonstrably valid (direct PIL access works), so this appears to be a context or environment issue rather than a file format problem.

## Additional Context
- **Project**: Home Assistant addon with live reload
- **Architecture**: Multi-zone cleaning task management with AI analysis
- **Test Pattern**: TDD with AAA (Arrange-Act-Assert) principles
- **Mock Strategy**: MockHAClient creates real file copies, MockGeminiClient handles AI responses
- **Integration Goal**: Test full workflow from camera snapshot ‚Üí AI analysis ‚Üí task processing

## Files Involved
- `aicleaner/aicleaner.py`: Main Zone class with failing Image.open calls
- `tests/mocks/mock_ha_api.py`: MockHAClient that copies real photo
- `tests/fixtures/messyroom.jpg`: Valid source photo (408x432 RGB JPEG)
- `tests/integration/test_zone_integration.py`: Failing integration tests

## Expected Behavior
Integration tests should:
1. Get camera snapshot (‚úÖ works)
2. Open image with PIL (‚ùå fails in Zone methods)
3. Call Gemini AI for analysis (never reached due to #2)
4. Process results and update state (never reached)

## Current Status
- **Unit test coverage**: 100% for core functionality
- **Integration test status**: 5/5 failing due to this PIL issue
- **Production readiness**: Core features work, but end-to-end validation blocked
